<?xml version="1.0" encoding="utf-8"?>
<!-- =================================================================================== -->
<!-- |    This document was autogenerated by xacro from robot.urdf.xacro               | -->
<!-- |    EDITING THIS FILE BY HAND IS NOT RECOMMENDED                                 | -->
<!-- =================================================================================== -->
<robot name="carbody_ur10_robot" version="2">
  <!-- Import Rviz colors -->
  <!--<xacro:include filename="$(find ur_description)/urdf/materials.xacro" />-->
  <!-- Create links -->
  <!-- link list-->
  <link name="world"/>
  <joint name="carbody_joint" type="fixed">
    <parent link="world"/>
    <child link="carbody_link"/>
    <origin rpy="0.0 0.0 0.0" xyz="0.0 0.0 0.0"/>
  </joint>
  <link name="carbody_link">
    <visual>
      <geometry>
        <mesh filename="package://pick_and_place_support/meshes/visual/carbody.dae"/>
      </geometry>
      <material name="LightGrey">
        <color rgba="0.7 0.7 0.7 1.0"/>
      </material>
    </visual>
    <collision>
      <geometry>
        <mesh convert="false" filename="package://pick_and_place_support/meshes/collision/carbody.stl"/>
      </geometry>
    </collision>
    <!--<collision_checking>
      <geometry>
        <convex_mesh filename="package://pick_and_place_support/meshes/carbody.stl" convert="false"/>
      </geometry>
    </collision_checking>-->
  </link>
  <joint name="drehkranz_joint" type="revolute">
    <parent link="world"/>
    <child link="drehkranz_link"/>
    <origin rpy="0.0 0.0 0.0" xyz="0.0 0.0 2.35"/>
    <axis xyz="0 0 1"/>
    <limit effort="1000" lower="-6.28" upper="6.28" velocity="20"/>
  </joint>
  <link name="drehkranz_link">
    <visual>
      <origin rpy="0.0 0.0 0.0" xyz="0.02 -0.05 -2.35"/>
      <geometry>
        <mesh filename="package://pick_and_place_support/meshes/visual/drehkranz.dae"/>
      </geometry>
      <material name="LightGrey">
        <color rgba="0.7 0.7 0.7 1.0"/>
      </material>
    </visual>
    <!--<collision>
            <origin xyz="0.02 -0.05 -2.35" rpy="0.0 0.0 0.0" />
            <geometry>
               <mesh filename="package://pick_and_place_support/meshes/drehkranz.stl" convert="false"/>
            </geometry>
         </collision>-->
    <collision_checking>
      <origin rpy="0.0 0.0 0.0" xyz="0.02 -0.05 -2.35"/>
      <geometry>
        <convex_mesh convert="false" filename="package://pick_and_place_support/meshes/collision/drehkranz.stl"/>
      </geometry>
    </collision_checking>
  </link>
  <joint name="base_joint" type="fixed">
    <parent link="drehkranz_link"/>
    <child link="base_link"/>
    <origin rpy="0.0 3.14 0.0" xyz="0.511 0.02 -0.83"/>
  </joint>
  <link name="container_link">
    <visual>
      <origin rpy="3.14 0.0 0.0" xyz="-1 0.95 1.2"/>
      <geometry>
        <mesh filename="package://pick_and_place_support/meshes/visual/container.stl" scale="0.001 0.001 0.001"/>
      </geometry>
      <material name="LightGrey">
        <color rgba="0.1 0.1 0.0 1"/>
      </material>
    </visual>
    <collision>
      <origin rpy="3.14 0.0 0.0" xyz="-1 0.95 1.2"/>
      <geometry>
        <mesh convert="false" filename="package://pick_and_place_support/meshes/collision/container.stl" scale="0.001 0.001 0.001"/>
      </geometry>
    </collision>
    <!--<collision_checking>
           <origin xyz="-1 0.95 1.2" rpy="3.14 0.0 0.0" />
           <geometry>
              <convex_mesh filename="package://pick_and_place_support/meshes/container.stl" scale="0.001 0.001 0.001" convert="false"/>
           </geometry>
      </collision_checking>-->
  </link>
  <joint name="container_joint" type="fixed">
    <parent link="world"/>
    <child link="container_link"/>
    <origin rpy="0.0 0.0 0.0" xyz="0.0 0.0 0.0"/>
  </joint>
  <link name="table_link">
    <visual>
      <origin rpy="0.0 0.0 0.0" xyz="-0.3 2.3 0"/>
      <geometry>
        <mesh filename="package://pick_and_place_support/meshes/visual/table.dae" scale="1.5 1 1.5"/>
      </geometry>
      <material name="LightGrey">
        <color rgba="0.1 0.1 0.0 1"/>
      </material>
    </visual>
    <collision_checking>
      <origin rpy="0.0 0.0 0.0" xyz="-0.3 2.3 0"/>
      <geometry>
        <convex_mesh convert="false" filename="package://pick_and_place_support/meshes/collision/table.stl" scale="1.5 1 1.5"/>
      </geometry>
    </collision_checking>
    <!--<collision>
         <origin xyz="-0.3 2.3 0" rpy="0.0 0.0 0.0" />
         <geometry>
            <mesh filename="package://pick_and_place_support/meshes/table.stl" scale="1.5 1 1.5" convert="false"/>
         </geometry>
    </collision>-->
  </link>
  <joint name="table_world_joint" type="fixed">
    <parent link="world"/>
    <child link="table_link"/>
    <origin rpy="0.0 0.0 0.0" xyz="0.0 0.0 0.0"/>
  </joint>
  <link name="conveyBelt_link">
    <visual>
      <origin rpy="0.0 0.0 0.0" xyz="-0.4 1.65 0.5"/>
      <geometry>
        <mesh filename="package://pick_and_place_support/meshes/visual/conveyBelt.dae" scale="1.5 1.2 1.5"/>
      </geometry>
      <material name="LightGrey">
        <color rgba="0.1 0.1 0.0 1"/>
      </material>
    </visual>
    <!--<collision_checking>
         <origin xyz="-0.4 1.65 0.5" rpy="0.0 0.0 0.0" />
         <geometry>
            <mesh filename="package://pick_and_place_support/meshes/conveyBelt.stl" scale="1.5 1.2 1.5" convert="false"/>
         </geometry>
    </collision_checking>-->
    <collision>
      <origin rpy="0.0 0.0 0.0" xyz="-0.4 1.65 0.5"/>
      <geometry>
        <mesh convert="false" filename="package://pick_and_place_support/meshes/collision/conveyBelt.stl" scale="1.5 1.2 1.5"/>
      </geometry>
    </collision>
  </link>
  <joint name="conveyBelt_table_joint" type="fixed">
    <parent link="table_link"/>
    <child link="conveyBelt_link"/>
    <origin rpy="0.0 0.0 0.0" xyz="0.0 0.0 0.0"/>
  </joint>
  <link name="greifer_link">
    <visual>
      <origin rpy="0.0 0.0 0.0" xyz="-0.35 0.3 0.02"/>
      <geometry>
        <mesh filename="package://pick_and_place_support/meshes/visual/greifer.dae" scale="1 1 1"/>
      </geometry>
      <material name="LightGrey">
        <color rgba="0.1 0.1 0.0 1"/>
      </material>
    </visual>
    <collision_checking>
      <origin rpy="0.0 0.0 0.0" xyz="-0.35 0.3 0.02"/>
      <geometry>
        <mesh convert="false" filename="package://pick_and_place_support/meshes/collision/greifer.stl" scale="1 1 1"/>
      </geometry>
    </collision_checking>
  </link>
  <joint name="greifer_wrist_3_link_joint" type="fixed">
    <parent link="wrist_3_link"/>
    <child link="greifer_link"/>
    <origin rpy="1.57 -0.785 0.0" xyz="0.0 0.3 0.0"/>
  </joint>
  <!--end of link list-->
  <!--
  Author: Kelsey Hawkins
  Contributers: Jimmy Da Silva, Ajit Krisshna N L, Muhammad Asif Rana
-->
  <!-- measured from model -->
  <link name="base_link">
    <visual>
      <geometry>
        <mesh filename="package://ur_description/meshes/ur10/visual/base.dae"/>
      </geometry>
      <material name="LightGrey">
        <color rgba="0.7 0.7 0.7 1.0"/>
      </material>
    </visual>
    <collision_checking>
      <geometry>
        <mesh convert="false" filename="package://ur_description/meshes/ur10/collision/base.stl"/>
      </geometry>
    </collision_checking>
    <inertial>
      <mass value="4.0"/>
      <origin rpy="0 0 0" xyz="0.0 0.0 0.0"/>
      <inertia ixx="0.0061063308908" ixy="0.0" ixz="0.0" iyy="0.0061063308908" iyz="0.0" izz="0.01125"/>
    </inertial>
  </link>
  <joint name="shoulder_pan_joint" type="revolute">
    <parent link="base_link"/>
    <child link="shoulder_link"/>
    <origin rpy="0.0 0.0 0.0" xyz="0.0 0.0 0.1273"/>
    <axis xyz="0 0 1"/>
    <limit effort="330.0" lower="-6.2831852" upper="6.2831852" velocity="2.16"/>
    <dynamics damping="0.0" friction="0.0"/>
  </joint>
  <link name="shoulder_link">
    <visual>
      <geometry>
        <mesh filename="package://ur_description/meshes/ur10/visual/shoulder.dae"/>
      </geometry>
      <material name="LightGrey">
        <color rgba="0.7 0.7 0.7 1.0"/>
      </material>
    </visual>
    <collision_checking>
      <geometry>
        <mesh convert="false" filename="package://ur_description/meshes/ur10/collision/shoulder.stl"/>
      </geometry>
    </collision_checking>
    <inertial>
      <mass value="7.778"/>
      <origin rpy="0 0 0" xyz="0.0 0.0 0.0"/>
      <inertia ixx="0.0314743125769" ixy="0.0" ixz="0.0" iyy="0.0314743125769" iyz="0.0" izz="0.021875625"/>
    </inertial>
  </link>
  <joint name="shoulder_lift_joint" type="revolute">
    <parent link="shoulder_link"/>
    <child link="upper_arm_link"/>
    <origin rpy="0.0 2.35619449019 0.0" xyz="0.0 0.220941 0.0"/>
    <axis xyz="0 1 0"/>
    <limit effort="330.0" lower="-6.2831852" upper="6.2831852" velocity="2.16"/>
    <dynamics damping="0.0" friction="0.0"/>
  </joint>
  <link name="upper_arm_link">
    <visual>
      <geometry>
        <mesh filename="package://ur_description/meshes/ur10/visual/upperarm.dae"/>
      </geometry>
      <material name="LightGrey">
        <color rgba="0.7 0.7 0.7 1.0"/>
      </material>
    </visual>
    <collision_checking>
      <geometry>
        <mesh convert="false" filename="package://ur_description/meshes/ur10/collision/upperarm.stl"/>
      </geometry>
    </collision_checking>
    <inertial>
      <mass value="12.93"/>
      <origin rpy="0 0 0" xyz="0.0 -0.045 0.306"/>
      <inertia ixx="0.421753803798" ixy="0.0" ixz="0.0" iyy="0.421753803798" iyz="0.0" izz="0.036365625"/>
    </inertial>
  </link>
  <joint name="elbow_joint" type="revolute">
    <parent link="upper_arm_link"/>
    <child link="forearm_link"/>
    <origin rpy="0.0 -1.57079632679 0.0" xyz="0.0 -0.1719 0.612"/>
    <axis xyz="0 1 0"/>
    <limit effort="150.0" lower="-6.2831852" upper="6.2831852" velocity="3.15"/>
    <dynamics damping="0.0" friction="0.0"/>
  </joint>
  <link name="forearm_link">
    <visual>
      <geometry>
        <mesh filename="package://ur_description/meshes/ur10/visual/forearm.dae"/>
      </geometry>
      <material name="LightGrey">
        <color rgba="0.7 0.7 0.7 1.0"/>
      </material>
    </visual>
    <collision_checking>
      <geometry>
        <mesh convert="false" filename="package://ur_description/meshes/ur10/collision/forearm.stl"/>
      </geometry>
    </collision_checking>
    <inertial>
      <mass value="3.87"/>
      <origin rpy="0 0 0" xyz="0.0 0.0 0.28615"/>
      <inertia ixx="0.111069694097" ixy="0.0" ixz="0.0" iyy="0.111069694097" iyz="0.0" izz="0.010884375"/>
    </inertial>
  </link>
  <joint name="wrist_1_joint" type="revolute">
    <parent link="forearm_link"/>
    <child link="wrist_1_link"/>
    <origin rpy="0.0 1.57079632679 0.0" xyz="0.0 0.0 0.5723"/>
    <axis xyz="0 1 0"/>
    <limit effort="54.0" lower="-6.2831852" upper="6.2831852" velocity="3.2"/>
    <dynamics damping="0.0" friction="0.0"/>
  </joint>
  <link name="wrist_1_link">
    <visual>
      <geometry>
        <mesh filename="package://ur_description/meshes/ur10/visual/wrist1.dae"/>
      </geometry>
      <material name="LightGrey">
        <color rgba="0.7 0.7 0.7 1.0"/>
      </material>
    </visual>
    <collision_checking>
      <geometry>
        <mesh convert="false" filename="package://ur_description/meshes/ur10/collision/wrist1.stl"/>
      </geometry>
    </collision_checking>
    <inertial>
      <mass value="1.96"/>
      <origin rpy="0 0 0" xyz="0.0 0.1149 0.0"/>
      <inertia ixx="0.0051082479567" ixy="0.0" ixz="0.0" iyy="0.0051082479567" iyz="0.0" izz="0.0055125"/>
    </inertial>
  </link>
  <joint name="wrist_2_joint" type="revolute">
    <parent link="wrist_1_link"/>
    <child link="wrist_2_link"/>
    <origin rpy="0.0 0.0 0.0" xyz="0.0 0.1149 0.0"/>
    <axis xyz="0 0 1"/>
    <limit effort="54.0" lower="-6.2831852" upper="6.2831852" velocity="3.2"/>
    <dynamics damping="0.0" friction="0.0"/>
  </joint>
  <link name="wrist_2_link">
    <visual>
      <geometry>
        <mesh filename="package://ur_description/meshes/ur10/visual/wrist2.dae"/>
      </geometry>
      <material name="LightGrey">
        <color rgba="0.7 0.7 0.7 1.0"/>
      </material>
    </visual>
    <collision_checking>
      <geometry>
        <mesh convert="false" filename="package://ur_description/meshes/ur10/collision/wrist2.stl"/>
      </geometry>
    </collision_checking>
    <inertial>
      <mass value="1.96"/>
      <origin rpy="0 0 0" xyz="0.0 0.0 0.1157"/>
      <inertia ixx="0.0051082479567" ixy="0.0" ixz="0.0" iyy="0.0051082479567" iyz="0.0" izz="0.0055125"/>
    </inertial>
  </link>
  <joint name="wrist_3_joint" type="revolute">
    <parent link="wrist_2_link"/>
    <child link="wrist_3_link"/>
    <origin rpy="0.0 0.0 0.0" xyz="0.0 0.0 0.1157"/>
    <axis xyz="0 1 0"/>
    <limit effort="54.0" lower="-6.2831852" upper="6.2831852" velocity="3.2"/>
    <dynamics damping="0.0" friction="0.0"/>
  </joint>
  <link name="wrist_3_link">
    <visual>
      <geometry>
        <mesh filename="package://ur_description/meshes/ur10/visual/wrist3.dae"/>
      </geometry>
      <material name="LightGrey">
        <color rgba="0.7 0.7 0.7 1.0"/>
      </material>
    </visual>
    <collision_checking>
      <geometry>
        <mesh convert="false" filename="package://ur_description/meshes/ur10/collision/wrist3.stl"/>
      </geometry>
    </collision_checking>
    <inertial>
      <mass value="0.202"/>
      <origin rpy="1.57079632679 0 0" xyz="0.0 0.07695 0.0"/>
      <inertia ixx="0.000117921661165" ixy="0.0" ixz="0.0" iyy="0.000117921661165" iyz="0.0" izz="0.000204525"/>
    </inertial>
  </link>
  <joint name="ee_fixed_joint" type="fixed">
    <parent link="wrist_3_link"/>
    <child link="ee_link"/>
    <origin rpy="1.57079632679 -0.785398163397 0" xyz="0.0 0.0922 0.0"/>
  </joint>
  <link name="ee_link">
    <collision>
      <geometry>
        <box size="0.01 0.01 0.01"/>
      </geometry>
      <origin rpy="0 0 0" xyz="-0.01 0 0"/>
    </collision>
  </link>
  <transmission name="shoulder_pan_trans">
    <type>transmission_interface/SimpleTransmission</type>
    <joint name="shoulder_pan_joint">
      <hardwareInterface>hardware_interface/PositionJointInterface</hardwareInterface>
    </joint>
    <actuator name="shoulder_pan_motor">
      <mechanicalReduction>1</mechanicalReduction>
    </actuator>
  </transmission>
  <transmission name="shoulder_lift_trans">
    <type>transmission_interface/SimpleTransmission</type>
    <joint name="shoulder_lift_joint">
      <hardwareInterface>hardware_interface/PositionJointInterface</hardwareInterface>
    </joint>
    <actuator name="shoulder_lift_motor">
      <mechanicalReduction>1</mechanicalReduction>
    </actuator>
  </transmission>
  <transmission name="elbow_trans">
    <type>transmission_interface/SimpleTransmission</type>
    <joint name="elbow_joint">
      <hardwareInterface>hardware_interface/PositionJointInterface</hardwareInterface>
    </joint>
    <actuator name="elbow_motor">
      <mechanicalReduction>1</mechanicalReduction>
    </actuator>
  </transmission>
  <transmission name="wrist_1_trans">
    <type>transmission_interface/SimpleTransmission</type>
    <joint name="wrist_1_joint">
      <hardwareInterface>hardware_interface/PositionJointInterface</hardwareInterface>
    </joint>
    <actuator name="wrist_1_motor">
      <mechanicalReduction>1</mechanicalReduction>
    </actuator>
  </transmission>
  <transmission name="wrist_2_trans">
    <type>transmission_interface/SimpleTransmission</type>
    <joint name="wrist_2_joint">
      <hardwareInterface>hardware_interface/PositionJointInterface</hardwareInterface>
    </joint>
    <actuator name="wrist_2_motor">
      <mechanicalReduction>1</mechanicalReduction>
    </actuator>
  </transmission>
  <transmission name="wrist_3_trans">
    <type>transmission_interface/SimpleTransmission</type>
    <joint name="wrist_3_joint">
      <hardwareInterface>hardware_interface/PositionJointInterface</hardwareInterface>
    </joint>
    <actuator name="wrist_3_motor">
      <mechanicalReduction>1</mechanicalReduction>
    </actuator>
  </transmission>
  <gazebo reference="shoulder_link">
    <selfCollide>true</selfCollide>
  </gazebo>
  <gazebo reference="upper_arm_link">
    <selfCollide>true</selfCollide>
  </gazebo>
  <gazebo reference="forearm_link">
    <selfCollide>true</selfCollide>
  </gazebo>
  <gazebo reference="wrist_1_link">
    <selfCollide>true</selfCollide>
  </gazebo>
  <gazebo reference="wrist_3_link">
    <selfCollide>true</selfCollide>
  </gazebo>
  <gazebo reference="wrist_2_link">
    <selfCollide>true</selfCollide>
  </gazebo>
  <gazebo reference="ee_link">
    <selfCollide>true</selfCollide>
  </gazebo>
  <!-- ROS base_link to UR 'Base' Coordinates transform -->
  <link name="base"/>
  <joint name="base_link-base_fixed_joint" type="fixed">
    <!-- NOTE: this rotation is only needed as long as base_link itself is
                 not corrected wrt the real robot (ie: rotated over 180
                 degrees)-->
    <origin rpy="0 0 -3.14159265359" xyz="0 0 0"/>
    <parent link="base_link"/>
    <child link="base"/>
  </joint>
  <!-- Frame coincident with all-zeros TCP on UR controller -->
  <link name="tool0"/>
  <joint name="wrist_3_link-tool0_fixed_joint" type="fixed">
    <origin rpy="-1.57079632679 0 0" xyz="0 0.0922 0"/>
    <parent link="wrist_3_link"/>
    <child link="tool0"/>
  </joint>
  <!-- Include robot -->
</robot>

